[2023-01-16T10:55:41.789+0000] {taskinstance.py:1087} INFO - Dependencies all met for <TaskInstance: our_dag_with_python_operator_v01.great manual__2023-01-16T10:32:50.482161+00:00 [queued]>
[2023-01-16T10:55:41.817+0000] {taskinstance.py:1087} INFO - Dependencies all met for <TaskInstance: our_dag_with_python_operator_v01.great manual__2023-01-16T10:32:50.482161+00:00 [queued]>
[2023-01-16T10:55:41.818+0000] {taskinstance.py:1283} INFO - 
--------------------------------------------------------------------------------
[2023-01-16T10:55:41.820+0000] {taskinstance.py:1284} INFO - Starting attempt 6 of 7
[2023-01-16T10:55:41.822+0000] {taskinstance.py:1285} INFO - 
--------------------------------------------------------------------------------
[2023-01-16T10:55:41.838+0000] {taskinstance.py:1304} INFO - Executing <Task(PythonOperator): great> on 2023-01-16 10:32:50.482161+00:00
[2023-01-16T10:55:41.850+0000] {standard_task_runner.py:55} INFO - Started process 4890 to run task
[2023-01-16T10:55:41.857+0000] {standard_task_runner.py:82} INFO - Running: ['***', 'tasks', 'run', 'our_dag_with_python_operator_v01', 'great', 'manual__2023-01-16T10:32:50.482161+00:00', '--job-id', '1618', '--raw', '--subdir', 'DAGS_FOLDER/create_dag_with_operator.py', '--cfg-path', '/tmp/tmpc5nsh6yy']
[2023-01-16T10:55:41.866+0000] {standard_task_runner.py:83} INFO - Job 1618: Subtask great
[2023-01-16T10:55:41.999+0000] {task_command.py:389} INFO - Running <TaskInstance: our_dag_with_python_operator_v01.great manual__2023-01-16T10:32:50.482161+00:00 [running]> on host c5d13f681a3d
[2023-01-16T10:55:42.100+0000] {taskinstance.py:1513} INFO - Exporting the following env vars:
AIRFLOW_CTX_DAG_OWNER=malo
AIRFLOW_CTX_DAG_ID=our_dag_with_python_operator_v01
AIRFLOW_CTX_TASK_ID=great
AIRFLOW_CTX_EXECUTION_DATE=2023-01-16T10:32:50.482161+00:00
AIRFLOW_CTX_TRY_NUMBER=6
AIRFLOW_CTX_DAG_RUN_ID=manual__2023-01-16T10:32:50.482161+00:00
[2023-01-16T10:55:42.106+0000] {taskinstance.py:1772} ERROR - Task failed with exception
Traceback (most recent call last):
  File "/home/airflow/.local/lib/python3.7/site-packages/airflow/operators/python.py", line 175, in execute
    return_value = self.execute_callable()
  File "/home/airflow/.local/lib/python3.7/site-packages/airflow/operators/python.py", line 192, in execute_callable
    return self.python_callable(*self.op_args, **self.op_kwargs)
  File "/opt/airflow/dags/create_dag_with_operator.py", line 17, in read_exel
    'opt/airflow/data/organizations-500000.xlsx')
  File "/home/airflow/.local/lib/python3.7/site-packages/pandas/util/_decorators.py", line 311, in wrapper
    return func(*args, **kwargs)
  File "/home/airflow/.local/lib/python3.7/site-packages/pandas/io/excel/_base.py", line 364, in read_excel
    io = ExcelFile(io, storage_options=storage_options, engine=engine)
  File "/home/airflow/.local/lib/python3.7/site-packages/pandas/io/excel/_base.py", line 1192, in __init__
    content_or_path=path_or_buffer, storage_options=storage_options
  File "/home/airflow/.local/lib/python3.7/site-packages/pandas/io/excel/_base.py", line 1071, in inspect_excel_format
    content_or_path, "rb", storage_options=storage_options, is_text=False
  File "/home/airflow/.local/lib/python3.7/site-packages/pandas/io/common.py", line 711, in get_handle
    handle = open(handle, ioargs.mode)
FileNotFoundError: [Errno 2] No such file or directory: 'opt/airflow/data/organizations-500000.xlsx'
[2023-01-16T10:55:42.122+0000] {taskinstance.py:1327} INFO - Marking task as UP_FOR_RETRY. dag_id=our_dag_with_python_operator_v01, task_id=great, execution_date=20230116T103250, start_date=20230116T105541, end_date=20230116T105542
[2023-01-16T10:55:42.137+0000] {standard_task_runner.py:105} ERROR - Failed to execute job 1618 for task great ([Errno 2] No such file or directory: 'opt/airflow/data/organizations-500000.xlsx'; 4890)
[2023-01-16T10:55:42.166+0000] {local_task_job.py:159} INFO - Task exited with return code 1
[2023-01-16T10:55:42.192+0000] {taskinstance.py:2582} INFO - 0 downstream tasks scheduled from follow-on schedule check
